Workbook

Sheet Product contribution
A1: Categories | B1: Key products | C1: Revenue contribution in 2022-23 (percent) | D1: Revenue contribution in 2022-23 (figures) | E1: Revenue contribution in 2023-24 (percent) | F1: Revenue contribution in 2023-24 (Figures) | G1: Revenue contribution in 2024-25 (percent) | H1: Revenue contribution in 2024-25 (Figures) | I1: Revenue contribution in 2025-26 (percent) | J1: Revenue contribution in 2025-26 (Figures)
A2: Food | B2: Groceries, staples, dairy | C2: 56.03 | D2: =42839.56*0.5603 -> 24003.005 | E2: 56.95 | F2: =50788.83*0.5695 -> 28924.239 | G2: 57.73 | H2: =59358.05*0.5773 -> 34267.402 | I2: 57.9 | J2: =68820.74*0.579 -> 39847.208
A3: Non Foods (FMCG) | B3: Home care products, personal care products | C3: 20.93 | D3: =42839.56*0.2093 -> 8966.3199 | E3: 20.68 | F3: =50788.83*0.2068 -> 10503.13 | G3: 20.01 | H3: =59358.05*0.2001 -> 11877.546 | I3: 19.82 | J3: =68820.74*0.1982 -> 13640.271
A4: General Merchandise & Apparel | B4: Bed & bath, toys & games, crockery, plastic goods, garments | C4: 23.04 | D4: =42839.56 * 0.2304 -> 9870.2346 | E4: 22.37 | F4: =50788.83*0.2237 -> 11361.461 | G4: 22.26 | H4: =59358.05*0.2226 -> 13213.102 | I4: 22.28 | J4: =68820.74*0.2228 -> 15333.261

Sheet Balance Sheet
A1: Balance Sheet
A3: Particulars | B3: FY22-23 | C3: FY23-24 | D3: FY24-25 | E3: FY25-26
A4: Assets
A5: Non-current assets
A6: Property, plant and equipment | B6: 9725.61 | C6: 11759.19 | D6: 14349.83 | E6: 17586.95
A7: Capital work-in-progress | B7: 829.16 | C7: 935.22 | D7: 1099.35 | E7: 1299.96
A8: Right -of- use assets | B8: 1504.88 | C8: 1539.1 | D8: 1741.73 | E8: 2381.41
A9: Investment properties | B9: 8.54 | C9: 8.09 | D9: 7.65 | E9: 7.26
A10: Goodwill | B10: 78.27 | C10: 78.27 | D10: 78.27 | E10: 78.27
A11: Intangible assets | B11: 23.18 | C11: 30.35 | D11: 28.98 | E11: 36.42
A12: Financial assets | B12: 108.56 | C12: 0.01 | D12: 2.01 | E12: 2.01
A13: Other non-current financial assets | C13: 234.76 | D13: 168.12 | E13: 196.71
A14: Income tax assets (net) | B14: 17.5 | C14: 17.56 | D14: 18.19 | E14: 16.8
A15: Deferred tax assets (net) | B15: 1.77 | C15: 4.72 | D15: 7.51 | E15: 6.71
A16: Other non-current assets | B16: 360.43 | C16: 367.9 | D16: 426.45 | E16: 433.98
A17: Total Non-Current Asset | B17: =SUM(B6:B16) -> 12657.9 | C17: =SUM(C6:C16) -> 14975.17 | D17: =SUM(D6:D16) -> 17928.09 | E17: =SUM(E6:E16) -> 22046.48
A19: Current Assets
A20: Inventories | B20: 3243.48 | C20: 3927.31 | D20: 5044.37 | E20: 5900.64
A21: Financial Assets
A22: Investments | B22: 202.19 | C22: 106.66 | D22: 1.25 | E22: 2
A23: Trade receivables | B23: 62.16 | C23: 166.37 | D23: 153.79 | E23: 149.34
A24: Cash and cash equivalents | B24: 207.15 | C24: 337.12 | D24: 355.48 | E24: 283.71
A25: Bank balances other than cash and cash equivalents | B25: 1201.18 | C25: 301.06 | D25: 2.72 | E25: 20.07
A26: Other current financial assets | B26: 316.77 | C26: 1128.49 | D26: 528.36 | E26: 726.6
A27: Other current assets | B27: 215.46 | C27: 235.02 | D27: 306.23 | E27: 395.42
A28: Total current assets | B28: =SUM(B20:B27) -> 5448.39 | C28: =SUM(C20:C27) -> 6202.03 | D28: =SUM(D20:D27) -> 6392.2 | E28: =SUM(E20:E27) -> 7477.78
A29: Total Assets | B29: =SUM(B17,B28) -> 18106.29 | C29: =SUM(C17,C28) -> 21177.2 | D29: =SUM(D17,D28) -> 24320.29 | E29: =SUM(E17,E28) -> 29524.26
A31: Liabilites
A32: Non-current liabilities
A33: Lease liability | B33: 476.66 | C33: 399.24 | D33: 555.79 | E33: 1142.54
A34: Other non-current financial liabilities | B34: 0.47 | C34: 0.37 | D34: 0.49 | E34: 0.54
A35: Provisions | B35: 6.41 | C35: 9.18 | D35: 12.67 | E35: 14.7
A36: Deferred tax liabilities (net) | B36: 76.96 | C36: 91.93 | D36: 112.48 | E36: 121.86
A37: Total Non-current liabilities | B37: =SUM(B33:B36) -> 560.5 | C37: =SUM(C33:C36) -> 500.72 | D37: =SUM(D33:D36) -> 681.43 | E37: =SUM(E33:E36) -> 1279.64
A39: Current liabilities
A40: Borrowings | E40: 965.27
A41: Lease liability | B41: 166.32 | C41: 192.92 | D41: 263.83 | E41: 317.18
A42: Trade payables – Micro & small enterprises | B42: 76.29 | C42: 230.6 | D42: 289.53 | E42: 393.47
A43: Trade payables – Other than micro & small | B43: 677.5 | C43: 754.21 | D43: 781.28 | E43: 944.76
A44: Other current financial liabilities | B44: 289.46 | C44: 389.85 | D44: 448.64 | E44: 637.19
...

Sheet Balance Sheet Trend analysis
A1: Balance Sheet Trend analysis
A3: Particulars | B3: FY22-23 | C3: FY23-24 | D3: FY24-25 | E3: FY25-26
A4: Assets
A5: Non-current assets
A6: Property, plant and equipment | B6: =('Balance Sheet'!B6/'Balance Sheet'!$B$29) -> 0.53713986 | C6: =('Balance Sheet'!C6/'Balance Sheet'!$C$29) -> 0.55527596 | D6: =('Balance Sheet'!D6/'Balance Sheet'!$D$29) -> 0.59003532 | E6: =('Balance Sheet'!E6/'Balance Sheet'!$E$29) -> 0.59567793
A7: Capital work-in-progress | B7: =('Balance Sheet'!B7/'Balance Sheet'!$B$29) -> 0.045794031 | C7: =('Balance Sheet'!C7/'Balance Sheet'!$C$29) -> 0.044161646 | D7: =('Balance Sheet'!D7/'Balance Sheet'!$D$29) -> 0.045202997 | E7: =('Balance Sheet'!E7/'Balance Sheet'!$E$29) -> 0.044030231
A8: Right -of- use assets | B8: =('Balance Sheet'!B8/'Balance Sheet'!$B$29) -> 0.083113658 | C8: =('Balance Sheet'!C8/'Balance Sheet'!$C$29) -> 0.072677219 | D8: =('Balance Sheet'!D8/'Balance Sheet'!$D$29) -> 0.071616334 | E8: =('Balance Sheet'!E8/'Balance Sheet'!$E$29) -> 0.080659431
A9: Investment properties | B9: =('Balance Sheet'!B9/'Balance Sheet'!$B$29) -> 0.0004716593 | C9: =('Balance Sheet'!C9/'Balance Sheet'!$C$29) -> 0.00038201462 | D9: =('Balance Sheet'!D9/'Balance Sheet'!$D$29) -> 0.00031455217 | E9: =('Balance Sheet'!E9/'Balance Sheet'!$E$29) -> 0.00024589947
A10: Goodwill | B10: =('Balance Sheet'!B10/'Balance Sheet'!$B$29) -> 0.0043228072 | C10: =('Balance Sheet'!C10/'Balance Sheet'!$C$29) -> 0.003695956 | D10: =('Balance Sheet'!D10/'Balance Sheet'!$D$29) -> 0.0032183004 | E10: =('Balance Sheet'!E10/'Balance Sheet'!$E$29) -> 0.0026510402
A11: Intangible assets | B11: =('Balance Sheet'!B11/'Balance Sheet'!$B$29) -> 0.0012802181 | C11: =('Balance Sheet'!C11/'Balance Sheet'!$C$29) -> 0.0014331451 | D11: =('Balance Sheet'!D11/'Balance Sheet'!$D$29) -> 0.0011915976 | E11: =('Balance Sheet'!E11/'Balance Sheet'!$E$29) -> 0.0012335618
A12: Financial assets | B12: =('Balance Sheet'!B12/'Balance Sheet'!$B$29) -> 0.0059957065 | C12: =('Balance Sheet'!C12/'Balance Sheet'!$C$29) -> 4.7220596e-07 | D12: =('Balance Sheet'!D12/'Balance Sheet'!$D$29) -> 8.2647041e-05 | E12: =('Balance Sheet'!E12/'Balance Sheet'!$E$29) -> 6.8079606e-05
A13: Other non-current financial assets | B13: =('Balance Sheet'!B13/'Balance Sheet'!$B$29) -> 0 | C13: =('Balance Sheet'!C13/'Balance Sheet'!$C$29) -> 0.011085507 | D13: =('Balance Sheet'!D13/'Balance Sheet'!$D$29) -> 0.0069127465 | E13: =('Balance Sheet'!E13/'Balance Sheet'!$E$29) -> 0.0066626564
A14: Income tax assets (net) | B14: =('Balance Sheet'!B14/'Balance Sheet'!$B$29) -> 0.00096651495 | C14: =('Balance Sheet'!C14/'Balance Sheet'!$C$29) -> 0.00082919366 | D14: =('Balance Sheet'!D14/'Balance Sheet'!$D$29) -> 0.00074793516 | E14: =('Balance Sheet'!E14/'Balance Sheet'!$E$29) -> 0.00056902358
A15: Deferred tax assets (net) | B15: =('Balance Sheet'!B15/'Balance Sheet'!$B$29) -> 9.7756084e-05 | C15: =('Balance Sheet'!C15/'Balance Sheet'!$C$29) -> 0.00022288121 | D15: =('Balance Sheet'!D15/'Balance Sheet'!$D$29) -> 0.00030879566 | E15: =('Balance Sheet'!E15/'Balance Sheet'!$E$29) -> 0.00022727073
A16: Other non-current assets | B16: =('Balance Sheet'!B16/'Balance Sheet'!$B$29) -> 0.019906342 | C16: =('Balance Sheet'!C16/'Balance Sheet'!$C$29) -> 0.017372457 | D16: =('Balance Sheet'!D16/'Balance Sheet'!$D$29) -> 0.017534742 | E16: =('Balance Sheet'!E16/'Balance Sheet'!$E$29) -> 0.014699098
A17: Total Non-Current Asset | B17: ='Balance Sheet'!B17/'Balance Sheet'!B29 -> 0.69908855 | C17: ='Balance Sheet'!C17/'Balance Sheet'!C29 -> 0.70713645 | D17: ='Balance Sheet'!D17/'Balance Sheet'!D29 -> 0.73716596 | E17: ='Balance Sheet'!E17/'Balance Sheet'!E29 -> 0.74672422
A19: Current Assets
A20: Inventories | B20: ='Balance Sheet'!B20/'Balance Sheet'!$B$29 -> 0.17913554 | C20: ='Balance Sheet'!C20/'Balance Sheet'!$C$29 -> 0.18544992 | D20: ='Balance Sheet'!D20/'Balance Sheet'!$D$29 -> 0.20741406 | E20: ='Balance Sheet'!E20/'Balance Sheet'!$E$29 -> 0.19985734
A21: Financial Assets | B21: ='Balance Sheet'!B21/'Balance Sheet'!$B$29 -> 0 | C21: ='Balance Sheet'!C21/'Balance Sheet'!$C$29 -> 0 | D21: ='Balance Sheet'!D21/'Balance Sheet'!$D$29 -> 0 | E21: ='Balance Sheet'!E21/'Balance Sheet'!$E$29 -> 0
A22: Investments | B22: ='Balance Sheet'!B22/'Balance Sheet'!$B$29 -> 0.011166838 | C22: ='Balance Sheet'!C22/'Balance Sheet'!$C$29 -> 0.0050365487 | D22: ='Balance Sheet'!D22/'Balance Sheet'!$D$29 -> 5.1397413e-05 | E22: ='Balance Sheet'!E22/'Balance Sheet'!$E$29 -> 6.7740902e-05
A23: Trade receivables | B23: ='Balance Sheet'!B23/'Balance Sheet'!$B$29 -> 0.0034330611 | C23: ='Balance Sheet'!C23/'Balance Sheet'!$C$29 -> 0.0078560905 | D23: ='Balance Sheet'!D23/'Balance Sheet'!$D$29 -> 0.0063235266 | E23: ='Balance Sheet'!E23/'Balance Sheet'!$E$29 -> 0.0050582131
A24: Cash and cash equivalents | B24: ='Balance Sheet'!B24/'Balance Sheet'!$B$29 -> 0.011440776 | C24: ='Balance Sheet'!C24/'Balance Sheet'!$C$29 -> 0.015919007 | D24: ='Balance Sheet'!D24/'Balance Sheet'!$D$29 -> 0.014616602 | E24: ='Balance Sheet'!E24/'Balance Sheet'!$E$29 -> 0.0096093856
A25: Bank balances other than cash and cash equivalents | B25: ='Balance Sheet'!B25/'Balance Sheet'!$B$29 -> 0.066340482 | C25: ='Balance Sheet'!C25/'Balance Sheet'!$C$29 -> 0.014216233 | D25: ='Balance Sheet'!D25/'Balance Sheet'!$D$29 -> 0.00011184077 | E25: ='Balance Sheet'!E25/'Balance Sheet'!$E$29 -> 0.00067977995
A26: Other current financial assets | B26: ='Balance Sheet'!B26/'Balance Sheet'!$B$29 -> 0.017495025 | C26: ='Balance Sheet'!C26/'Balance Sheet'!$C$29 -> 0.05328797 | D26: ='Balance Sheet'!D26/'Balance Sheet'!$D$29 -> 0.02172507 | E26: ='Balance Sheet'!E26/'Balance Sheet'!$E$29 -> 0.02461027
A27: Other current assets | B27: ='Balance Sheet'!B27/'Balance Sheet'!$B$29 -> 0.011899732 | C27: ='Balance Sheet'!C27/'Balance Sheet'!$C$29 -> 0.011097784 | D27: ='Balance Sheet'!D27/'Balance Sheet'!$D$29 -> 0.012591544 | E27: ='Balance Sheet'!E27/'Balance Sheet'!$E$29 -> 0.013393054
A28: Total current assets | B28: ='Balance Sheet'!B28/'Balance Sheet'!B29 -> 0.30091145 | C28: ='Balance Sheet'!C28/'Balance Sheet'!C29 -> 0.29286355 | D28: ='Balance Sheet'!D28/'Balance Sheet'!D29 -> 0.26283404 | E28: ='Balance Sheet'!E28/'Balance Sheet'!E29 -> 0.25327578
A29: Total Asset | B29: =SUM(B17,B28) -> 1 | C29: =SUM(C17,C28) -> 1 | D29: =SUM(D17,D28) -> 1 | E29: =SUM(E17,E28) -> 1
A31: Liabilites
A32: Non-current liabilities
A33: Lease liability | B33: ='Balance Sheet'!B33/'Balance Sheet'!$B$53 -> 0.026325658 | C33: ='Balance Sheet'!C33/'Balance Sheet'!$C$53 -> 0.018852351 | D33: ='Balance Sheet'!D33/'Balance Sheet'!$D$53 -> 0.022852935 | E33: ='Balance Sheet'!E33/'Balance Sheet'!$E$53 -> 0.038698345
A34: Other non-current financial liabilities | B34: ='Balance Sheet'!B34/'Balance Sheet'!$B$53 -> 2.595783e-05 | C34: ='Balance Sheet'!C34/'Balance Sheet'!$C$53 -> 1.747162e-05 | D34: ='Balance Sheet'!D34/'Balance Sheet'!$D$53 -> 2.0147786e-05 | E34: ='Balance Sheet'!E34/'Balance Sheet'!$E$53 -> 1.8290044e-05
A35: Provisions | B35: ='Balance Sheet'!B35/'Balance Sheet'!$B$53 -> 0.00035402062 | C35: ='Balance Sheet'!C35/'Balance Sheet'!$C$53 -> 0.00043348507 | D35: ='Balance Sheet'!D35/'Balance Sheet'!$D$53 -> 0.00052096418 | E35: ='Balance Sheet'!E35/'Balance Sheet'!$E$53 -> 0.00049789563
A36: Deferred tax liabilities (net) | B36: ='Balance Sheet'!B36/'Balance Sheet'!$B$53 -> 0.0042504566 | C36: ='Balance Sheet'!C36/'Balance Sheet'!$C$53 -> 0.0043409894 | D36: ='Balance Sheet'!D36/'Balance Sheet'!$D$53 -> 0.0046249449 | E36: ='Balance Sheet'!E36/'Balance Sheet'!$E$53 -> 0.0041274532
A37: Total Non-current liabilities | B37: ='Balance Sheet'!B37/'Balance Sheet'!B53 -> 0.030956093 | C37: ='Balance Sheet'!C37/'Balance Sheet'!C53 -> 0.023644297 | D37: ='Balance Sheet'!D37/'Balance Sheet'!D53 -> 0.028018992 | E37: ='Balance Sheet'!E37/'Balance Sheet'!E53 -> 0.043341984
A39: Current liabilities
A40: Borrowings | B40: ='Balance Sheet'!B40/'Balance Sheet'!$B$53 -> 0 | C40: ='Balance Sheet'!C40/'Balance Sheet'!$C$53 -> 0 | D40: ='Balance Sheet'!D40/'Balance Sheet'!$D$53 -> 0 | E40: ='Balance Sheet'!E40/'Balance Sheet'!$E$53 -> 0.03269413
A41: Lease liability | B41: ='Balance Sheet'!B41/'Balance Sheet'!$B$53 -> 0.0091857581 | C41: ='Balance Sheet'!C41/'Balance Sheet'!$C$53 -> 0.0091097973 | D41: ='Balance Sheet'!D41/'Balance Sheet'!$D$53 -> 0.010848144 | E41: ='Balance Sheet'!E41/'Balance Sheet'!$E$53 -> 0.01074303
A42: Trade payables – Micro & small enterprises | B42: ='Balance Sheet'!B42/'Balance Sheet'!$B$53 -> 0.0042134529 | C42: ='Balance Sheet'!C42/'Balance Sheet'!$C$53 -> 0.010889069 | D42: ='Balance Sheet'!D42/'Balance Sheet'!$D$53 -> 0.011904874 | E42: ='Balance Sheet'!E42/'Balance Sheet'!$E$53 -> 0.013327006
A43: Trade payables – Other than micro & small | B43: ='Balance Sheet'!B43/'Balance Sheet'!$B$53 -> 0.037417936 | C43: ='Balance Sheet'!C43/'Balance Sheet'!$C$53 -> 0.035614246 | D43: ='Balance Sheet'!D43/'Balance Sheet'!$D$53 -> 0.032124617 | E43: ='Balance Sheet'!E43/'Balance Sheet'!$E$53 -> 0.031999447
A44: Other current financial liabilities | B44: ='Balance Sheet'!B44/'Balance Sheet'!$B$53 -> 0.01598671 | C44: ='Balance Sheet'!C44/'Balance Sheet'!$C$53 -> 0.018408949 | D44: ='Balance Sheet'!D44/'Balance Sheet'!$D$53 -> 0.018447148 | E44: ='Balance Sheet'!E44/'Balance Sheet'!$E$53 -> 0.021581913
...

Sheet income statement
A1: Income statement
A4: Particulars | B4: FY22-23 | C4: FY23-24 | D4: FY24-25 | E4: FY25-26
A5: Revenue from operations | B5: 42839.56 | C5: 50788.83 | D5: 59358.05 | E5: 68820.74
A7: Operating Expenses
A8: Purchase of stock-in-trade | B8: 36884.77 | C8: 43958.31 | D8: 51668.76 | E8: 59315.99
A9: Changes in inventories of stock-in-trade | B9: -500.82 | C9: -683.77 | D9: -1117.06 | E9: -856.26
A10: Employee benefits expenses | B10: 746.97 | C10: 906.12 | D10: 1165.9 | E10: 1541.48
A11: Other expenses | B11: 2071.61 | C11: 2504.4 | D11: 3153.12 | E11: 3632.94
A12: Total Expenses | B12: =SUM(B8:B11) -> 39202.53 | C12: =SUM(C8:C11) -> 46685.06 | D12: =SUM(D8:D11) -> 54870.72 | E12: =SUM(E8:E11) -> 63634.15
A14: EBITDA | B14: =B5-B12 -> 3637.03 | C14: =C5-C12 -> 4103.77 | D14: =D5-D12 -> 4487.33 | E14: =E5-E12 -> 5186.59
A15: Depreciation and amortisation expenses | B15: 638.87 | C15: 730.76 | D15: 869.52 | E15: 1037.02
A17: EBIT (opearting profit) | B17: =B14-B15 -> 2998.16 | C17: =C14-C15 -> 3373.01 | D17: =D14-D15 -> 3617.81 | E17: =E14-E15 -> 4149.57
A18: Finance costs | B18: 67.41 | C18: -58.13 | D18: -69.45 | E18: -142.05
A19: Other income | B19: 129.34 | C19: 146.45 | D19: 124.31 | E19: 74.1
A21: Profit Before Tax | B21: =B17+B19-B18 -> 3060.09 | C21: =SUM(C17:C19) -> 3461.33 | D21: =SUM(D17:D19) -> 3672.67 | E21: =SUM(E17:E19) -> 4081.62
A22: Total Tax Expenses | B22: 681.75 | C22: 925.72 | D22: 965.22 | E22: 1111.76
A24: Profit after tax/ Net Profit | B24: =B21-B22 -> 2378.34 | C24: =C21-C22 -> 2535.61 | D24: =D21-D22 -> 2707.45 | E24: =E21-E22 -> 2969.86
A25: Less: OCI loss after tax | C25: -8.81 | D25: -8.81 | E25: -5.48
A26: Total Comprehensive income | B26: =B24 -> 2378.34 | C26: =C24+C25 -> 2526.8 | D26: =D24+D25 -> 2698.64 | E26: =E24+E25 -> 2964.38

Sheet income statement Trend Analysis
A1: Income Statement Trend Analysis
A4: Particulars | B4: FY22-23 | C4: FY23-24 | D4: FY24-25 | E4: FY25-26
A5: Revenue from operations | B5: ='income statement'!B5/'income statement'!B5 -> 1 | C5: ='income statement'!C5/'income statement'!C5 -> 1 | D5: ='income statement'!D5/'income statement'!D5 -> 1 | E5: ='income statement'!E5/'income statement'!E5 -> 1
A7: Operating Expenses
A8: Purchase of stock-in-trade | B8: ='income statement'!B8/'income statement'!$B$5 -> 0.86099787 | C8: ='income statement'!C8/'income statement'!$C$5 -> 0.86551137 | D8: ='income statement'!D8/'income statement'!$D$5 -> 0.87045919 | E8: ='income statement'!E8/'income statement'!$E$5 -> 0.8618912
A9: Changes in inventories of stock-in-trade | B9: ='income statement'!B9/'income statement'!$B$5 -> -0.011690596 | C9: ='income statement'!C9/'income statement'!$C$5 -> -0.013463 | D9: ='income statement'!D9/'income statement'!$D$5 -> -0.018819014 | E9: ='income statement'!E9/'income statement'!$E$5 -> -0.012441889
A10: Employee benefits expenses | B10: ='income statement'!B10/'income statement'!$B$5 -> 0.017436454 | C10: ='income statement'!C10/'income statement'!$C$5 -> 0.017840931 | D10: ='income statement'!D10/'income statement'!$D$5 -> 0.019641818 | E10: ='income statement'!E10/'income statement'!$E$5 -> 0.02239848
A11: Other expenses | B11: ='income statement'!B11/'income statement'!$B$5 -> 0.048357406 | C11: ='income statement'!C11/'income statement'!$C$5 -> 0.049310055 | D11: ='income statement'!D11/'income statement'!$D$5 -> 0.053120343 | E11: ='income statement'!E11/'income statement'!$E$5 -> 0.052788447
A12: Total Expenses | B12: ='income statement'!B12/'income statement'!$B$5 -> 0.91510114 | C12: ='income statement'!C12/'income statement'!$C$5 -> 0.91919936 | D12: ='income statement'!D12/'income statement'!$D$5 -> 0.92440233 | E12: ='income statement'!E12/'income statement'!$E$5 -> 0.92463624
A14: EBITDA | B14: ='income statement'!B14/'income statement'!$B$5 -> 0.084898865 | C14: ='income statement'!C14/'income statement'!$C$5 -> 0.080800641 | D14: ='income statement'!D14/'income statement'!$D$5 -> 0.075597665 | E14: ='income statement'!E14/'income statement'!$E$5 -> 0.075363764
A15: Depreciation and amortisation expenses | B15: =-'income statement'!B15/'income statement'!$B$5 -> -0.014913085 | C15: =-'income statement'!C15/'income statement'!$C$5 -> -0.014388203 | D15: =-'income statement'!D15/'income statement'!$D$5 -> -0.014648729 | E15: =-'income statement'!E15/'income statement'!$E$5 -> -0.015068423
A17: EBIT | B17: ='income statement'!B17/'income statement'!$B$5 -> 0.069985779 | C17: ='income statement'!C17/'income statement'!$C$5 -> 0.066412438 | D17: ='income statement'!D17/'income statement'!$D$5 -> 0.060948936 | E17: ='income statement'!E17/'income statement'!$E$5 -> 0.060295341
A18: Finance costs | B18: ='income statement'!B18/'income statement'!$B$5 -> 0.0015735456 | C18: ='income statement'!C18/'income statement'!$C$5 -> -0.001144543 | D18: ='income statement'!D18/'income statement'!$D$5 -> -0.0011700182 | E18: ='income statement'!E18/'income statement'!$E$5 -> -0.002064058
A19: Other income | B19: ='income statement'!B19/'income statement'!$B$5 -> 0.003019172 | C19: ='income statement'!C19/'income statement'!$C$5 -> 0.002883508 | D19: ='income statement'!D19/'income statement'!$D$5 -> 0.00209424 | E19: ='income statement'!E19/'income statement'!$E$5 -> 0.0010767103
A21: Profit Before Tax | B21: ='income statement'!B21/'income statement'!$B$5 -> 0.071431406 | C21: ='income statement'!C21/'income statement'!$C$5 -> 0.068151403 | D21: ='income statement'!D21/'income statement'!$D$5 -> 0.061873158 | E21: ='income statement'!E21/'income statement'!$E$5 -> 0.059307993
A22: Total Tax Expenses | B22: ='income statement'!B22/'income statement'!$B$5 -> 0.015914029 | C22: ='income statement'!C22/'income statement'!$C$5 -> 0.018226842 | D22: ='income statement'!D22/'income statement'!$D$5 -> 0.016260979 | E22: ='income statement'!E22/'income statement'!$E$5 -> 0.016154433
A24: Profit after tax/ Net Profit | B24: ='income statement'!B24/'income statement'!$B$5 -> 0.055517377 | C24: ='income statement'!C24/'income statement'!$C$5 -> 0.04992456 | D24: ='income statement'!D24/'income statement'!$D$5 -> 0.045612179 | E24: ='income statement'!E24/'income statement'!$E$5 -> 0.043153561
A25: Less: OCI loss after tax | B25: ='income statement'!B25/'income statement'!$B$5 -> 0 | C25: ='income statement'!C25/'income statement'!$C$5 -> -0.00017346334 | D25: ='income statement'!D25/'income statement'!$D$5 -> -0.00014842132 | E25: ='income statement'!E25/'income statement'!$E$5 -> -7.9627159e-05
A26: Total Comprehensive income | B26: ='income statement'!B26/'income statement'!$B$5 -> 0.055517377 | C26: ='income statement'!C26/'income statement'!$C$5 -> 0.049751097 | D26: ='income statement'!D26/'income statement'!$D$5 -> 0.045463758 | E26: ='income statement'!E26/'income statement'!$E$5 -> 0.043073934

Sheet Cash flow
A1: Cash Flow
A4: Particulars | B4: FY22-23 | C4: FY23-24 | D4: FY24-25 | E4: FY25-26
A5: Net cash flow from operating activites | B5: 2630.27 | C5: 2745.84 | D5: 2462.97 | E5: 3466.74
A7: Capex | B7: 2211.49 | C7: 2731.04 | D7: 3423.04 | E7: 4113.35
A8: Free cash flow (FCF) | B8: =B5-B7 -> 418.78 | C8: =C5-C7 -> 14.8 | D8: =D5-D7 -> -960.07 | E8: =E5-E7 -> -646.61

Sheet Ratio analysis
A1: Ratio Analysis
A4: Particulars | B4: FY22-23 | C4: FY23-24 | D4: FY24-25 | E4: FY25-26
A5: Net Sales | B5: ='income statement'!B5 -> 42839.56 | C5: ='income statement'!C5 -> 50788.83 | D5: ='income statement'!D5 -> 59358.05 | E5: ='income statement'!E5 -> 68820.74
A7: Sales growth % | B7: =(B5-31976.27)/31976.27 -> 0.33972974 | C7: =(C5-B5)/B5 -> 0.1855591 | D7: =(D5-C5)/C5 -> 0.16872253 | E7: =(E5-D5)/D5 -> 0.15941713
A8: Gross profit | B8: 6455.61 | C8: 7514.29 | D8: 8806.35 | E8: 10361.01
A9: Revenue CAGR | D9: =('income statement'!D5/'income statement'!B5)^(1/3)-1 -> 0.11483743 | E9: =('income statement'!E5/'income statement'!B5)^(1/4)-1 -> 0.12581903
A11: Liquidity
A12: Current Assest | B12: 5448.39 | C12: 6202.03 | D12: 6392.2 | E12: 7477.78
A13: Current Liabilities | B13: 1467.01 | C13: 1979.14 | D13: 2212.16 | E13: 3782.26
A14: Current Ratio | B14: =B12/B13 -> 3.713942 | C14: =C12/C13 -> 3.1336995 | D14: =D12/D13 -> 2.889574 | E14: =E12/E13 -> 1.9770666
A16: Profitability
A17: EBITDA | B17: ='income statement'!B14 -> 3637.03 | C17: ='income statement'!C14 -> 4103.77 | D17: ='income statement'!D14 -> 4487.33 | E17: ='income statement'!E14 -> 5186.59
A18: EBITDA Margin | B18: =B17/B5 -> 0.084898865 | C18: =C17/C5 -> 0.080800641 | D18: =D17/D5 -> 0.075597665 | E18: =E17/E5 -> 0.075363764
A19: Gross profit margin | B19: 0.15069272 | C19: 0.14795163 | D19: 0.14835983 | E19: 0.15055069
A20: Net profit margin | B20: ='income statement'!B26/'income statement'!B5 -> 0.055517377 | C20: ='income statement'!C26/'income statement'!C5 -> 0.049751097 | D20: ='income statement'!D26/'income statement'!D5 -> 0.045463758 | E20: ='income statement'!E26/'income statement'!E5 -> 0.043073934
A23: ROE | B23: ='income statement'!B26/('Balance Sheet'!B50+'Balance Sheet'!B49) -> 0.14791868 | C23: ='income statement'!C26/('Balance Sheet'!C50+'Balance Sheet'!C49) -> 0.13513875 | D23: ='income statement'!D26/('Balance Sheet'!D50+'Balance Sheet'!D49) -> 0.12594136 | E23: ='income statement'!E26/('Balance Sheet'!E50+'Balance Sheet'!E49) -> 0.12117295
A24: Net profit/ Net sales | B24: ='income statement'!B26/'Ratio analysis'!B5 -> 0.055517377 | C24: ='income statement'!C26/'Ratio analysis'!C5 -> 0.049751097 | D24: ='income statement'!D26/'Ratio analysis'!D5 -> 0.045463758 | E24: ='income statement'!E26/'Ratio analysis'!E5 -> 0.043073934
A25: Net sales / Total Asset | B25: =B5/'Balance Sheet'!B29 -> 2.3660043 | C25: =C5/'Balance Sheet'!C29 -> 2.3982788 | D25: =D5/'Balance Sheet'!D29 -> 2.4406802 | E25: =E5/'Balance Sheet'!E29 -> 2.3309895
A26: Total Asset/Shareholders Equity | B26: ='Balance Sheet'!B29/('Balance Sheet'!B50+'Balance Sheet'!B49) -> 1.1261041 | C26: ='Balance Sheet'!C29/('Balance Sheet'!C50+'Balance Sheet'!C49) -> 1.1326026 | D26: ='Balance Sheet'!D29/('Balance Sheet'!D50+'Balance Sheet'!D49) -> 1.1349904 | E26: ='Balance Sheet'!E29/('Balance Sheet'!E50+'Balance Sheet'!E49) -> 1.2068432
A29: Debt/Equity (Capital structure) | B29: ='Balance Sheet'!B40/('Balance Sheet'!B50+'Balance Sheet'!B49) -> 0 | C29: ='Balance Sheet'!C40/('Balance Sheet'!C50+'Balance Sheet'!C49) -> 0 | D29: ='Balance Sheet'!D40/('Balance Sheet'!D50+'Balance Sheet'!D49) -> 0 | E29: ='Balance Sheet'!E40/('Balance Sheet'!E50+'Balance Sheet'!E49) -> 0.039456688
A31: Efficency Ratios
A32: Inventory Turnover | B32: =( 'income statement'!B8+'income statement'!B9)/(( 3243.48 +2742.66 )/2) -> 12.156064 | C32: =('income statement'!C8+'income statement'!C9)/(( 3927.31 +3243.54)/2) -> 12.069571 | D32: =('income statement'!D8+'income statement'!D9)/(( 5044.37 + 3927.31 )/2) -> 11.269171 | E32: =('income statement'!E8+'income statement'!E9)/((5900.64 + 5044.37)/2) -> 10.682444 | G32: Ideal is 8 to 10+
A33: Asset Turnover | B33: ='income statement'!B5/(( 15472.64 +'Balance Sheet'!B29)/2) -> 2.5515739 | C33: ='income statement'!C5/(('Balance Sheet'!B29+'Balance Sheet'!C29)/2) -> 2.5857596 | D33: ='income statement'!D5/(('Balance Sheet'!D29+'Balance Sheet'!C29)/2) -> 2.609289 | E33: ='income statement'!E5/(('Balance Sheet'!E29+'Balance Sheet'!D29)/2) -> 2.5562751
A35: Cash flow ratios
A36: Free cash flow margins | B36: ='Cash flow'!B8/'income statement'!B5 -> 0.0097755439 | C36: ='Cash flow'!C8/'income statement'!C5 -> 0.00029140266 | D36: ='Cash flow'!D8/'income statement'!D5 -> -0.016174217 | E36: ='Cash flow'!E8/'income statement'!E5 -> -0.0093955688
A37: Cash conversion ratio | B37: ='Cash flow'!B5/'income statement'!B26 -> 1.1059268 | C37: ='Cash flow'!C5/'income statement'!C26 -> 1.0866867 | D37: ='Cash flow'!D5/'income statement'!D26 -> 0.91267083 | E37: ='Cash flow'!E5/'income statement'!E26 -> 1.1694655
A39: Capex to sales ( track store expansion intensity) | B39: ='Cash flow'!B7/'income statement'!B5 -> 0.051622612 | C39: ='Cash flow'!C7/'income statement'!C5 -> 0.053772454 | D39: ='Cash flow'!D7/'income statement'!D5 -> 0.057667663 | E39: ='Cash flow'!E7/'income statement'!E5 -> 0.059769046

Sheet Data
B1: Revenue | C1: Net profit | D1: Net profit margin | G1: Revenue | H1: Stores | I1: Revenue per store | J1: Revenue per store growth %
A2: {=TRANSPOSE('Ratio analysis'!B4:E4)} -> FY22-23 | B2: {=TRANSPOSE('income statement'!B5:E5)} -> 42839.56 | C2: {=TRANSPOSE('income statement'!B26:E26)} -> 2378.34 | D2: =C2/B2 -> 0.055517377 | F2: FY22-23 | G2: 42839.56 | H2: 324 | I2: =G2/H2 -> 132.22086 | J2: 22.149491
A3: FY23-24 | B3: 50788.83 | C3: 2526.8 | D3: =C3/B3 -> 0.049751097 | F3: FY23-24 | G3: 50788.83 | H3: 365 | I3: =G3/H3 -> 139.14748 | J3: =(I3-I2)-1 -> 5.9266153
A4: FY24-25 | B4: 59358.05 | C4: 2698.64 | D4: =C4/B4 -> 0.045463758 | F4: FY24-25 | G4: 59358.05 | H4: 415 | I4: =G4/H4 -> 143.03145 | J4: =(I4-I3)-1 -> 2.8839663
A5: FY25-26 | B5: 68820.74 | C5: 2964.38 | D5: =C5/B5 -> 0.043073934 | F5: FY25-26 | G5: 68820.74 | H5: 500 | I5: =G5/H5 -> 137.64148 | J5: =(I5-I4)-1 -> -6.3899658
B8: Operating Profit | C8: Net Op Profit | D8: Net Profit | G8: Net profit | H8: Operating Cash flow
A9: FY22-23 | B9: {=TRANSPOSE('income statement'!B17:E17)} -> 2998.16 | C9: =B9*(1-22.28%) -> 2330.17 | D9: {=TRANSPOSE('income statement'!B26:E26)} -> 2378.34 | F9: FY22-23 | G9: {=TRANSPOSE('income statement'!B26:E26)} -> 2378.34 | H9: {=TRANSPOSE('Cash flow'!B5:E5)} -> 2630.27
A10: FY23-24 | B10: 3373.01 | C10: =B10*(1-26.74%) -> 2471.0671 | D10: 2526.8 | F10: FY23-24 | G10: 2526.8 | H10: 2745.84
A11: FY24-25 | B11: 3617.81 | C11: =B11*(1-26.28%) -> 2667.0495 | D11: 2698.64 | F11: FY24-25 | G11: 2698.64 | H11: 2462.97
A12: FY25-26 | B12: 4149.57 | C12: =B12*(1-27.24%) -> 3019.2271 | D12: 2964.38 | F12: FY25-26 | G12: 2964.38 | H12: 3466.74
B14: Sales growth % | C14: Inventory Growth
A15: FY22-23 | B15: {=TRANSPOSE('Ratio analysis'!B7:E7)} -> 0.33972974 | C15: =('Balance Sheet'!B20- 2742.66 )/ 2742.66 -> 0.18260375
A16: FY23-24 | B16: 0.1855591 | C16: =('Balance Sheet'!C20-'Balance Sheet'!B20)/'Balance Sheet'!B20 -> 0.21083219
A17: FY24-25 | B17: 0.16872253 | C17: =('Balance Sheet'!D20-'Balance Sheet'!C20)/'Balance Sheet'!C20 -> 0.28443387
A18: FY25-26 | B18: 0.15941713 | C18: =('Balance Sheet'!E20-'Balance Sheet'!D20)/'Balance Sheet'!D20 -> 0.16974766

Sheet Visualization

Sheet P&L Assumptions
A1: P&L Assumptions | G1: Scenarios
A2: Selected Scenario | C2: 2 | G2: Case A | I2: Optimistic | J2: Higher than historical average
G3: Case B | I3: Base | J3: Historical Pattern
G4: Case C | I4: Worst | J4: Worse than historical average
G6: Forcast Years
A7: INR in Crore | B7: FY22-23 | C7: FY23-24 | D7: FY24-25 | E7: FY25-26 | G7: FY26-27 | H7: FY27-28 | I7: FY28-29 | J7: FY29-30 | K7: FY30-31 | L7: FY31-32 | M7: FY32-33 | N7: FY33-34
A8: Revenue | B8: 42839.56 | C8: 50788.83 | D8: 59358.05 | E8: 68820.74 | G8: =E8*(1+G9) -> 79969.7 | H8: =G8*(1+H9) -> 92764.852 | I8: =H8*(1+I9) -> 107421.7 | J8: =I8*(1+J9) -> 124072.06 | K8: =J8*(1+K9) -> 143303.23 | L8: =K8*(1+L9) -> 165515.23 | M8: =L8*(1+M9) -> 191170.09 | N8: =M8*(1+N9) -> 220801.46
A9: Growth % | C9: =(C8-B8)/B8 -> 0.1855591 | D9: =(D8-C8)/C8 -> 0.16872253 | E9: =(E8-D8)/D8 -> 0.15941713 | G9: =CHOOSE($C$2,G11,G12,G13,) -> 0.162 | H9: =CHOOSE($C$2,H11,H12,H13,) -> 0.16 | I9: =CHOOSE($C$2,I11,I12,I13,) -> 0.158 | J9: =CHOOSE($C$2,J11,J12,J13,) -> 0.155 | K9: =CHOOSE($C$2,K11,K12,K13,) -> 0.155 | L9: =CHOOSE($C$2,L11,L12,L13,) -> 0.155 | M9: =CHOOSE($C$2,M11,M12,M13,) -> 0.155 | N9: =CHOOSE($C$2,N11,N12,N13,) -> 0.155
A11: Case 1 | G11: 0.2 | H11: 0.2 | I11: 0.2 | J11: 0.2 | K11: 0.2 | L11: 0.2 | M11: 0.2 | N11: 0.2
A12: Case 2 | G12: 0.162 | H12: 0.16 | I12: 0.158 | J12: 0.155 | K12: =J12 -> 0.155 | L12: =K12 -> 0.155 | M12: =L12 -> 0.155 | N12: =M12 -> 0.155
A13: Case 3 | G13: 0.14 | H13: 0.14 | I13: 0.14 | J13: 0.14 | K13: 0.14 | L13: 0.14 | M13: 0.14 | N13: 0.14
A15: Cost of material Consumed | B15: ='income statement'!B8+'income statement'!B9 -> 36383.95 | C15: ='income statement'!C8+'income statement'!C9 -> 43274.54 | D15: ='income statement'!D8+'income statement'!D9 -> 50551.7 | E15: ='income statement'!E8+'income statement'!E9 -> 58459.73 | G15: =E15*(1+G16) -> 67520.988 | H15: =G15*(1+H16) -> 77649.136 | I15: =H15*(1+I16) -> 88520.015 | J15: =I15*(1+J16) -> 100912.82 | K15: =J15*(1+K16) -> 114838.79 | L15: =K15*(1+L16) -> 130686.54 | M15: =L15*(1+M16) -> 148721.28 | N15: =M15*(1+N16) -> 169244.82
A16: Growth % | C16: =(C15-B15)/B15 -> 0.18938543 | D16: =(D15-C15)/C15 -> 0.16816262 | E16: =(E15-D15)/D15 -> 0.1564345 | G16: =CHOOSE($C$2,G18,G19,G20) -> 0.155 | H16: =CHOOSE($C$2,H18,H19,H20) -> 0.15 | I16: =CHOOSE($C$2,I18,I19,I20) -> 0.14 | J16: =CHOOSE($C$2,J18,J19,J20) -> 0.14 | K16: =CHOOSE($C$2,K18,K19,K20) -> 0.138 | L16: =CHOOSE($C$2,L18,L19,L20) -> 0.138 | M16: =CHOOSE($C$2,M18,M19,M20) -> 0.138 | N16: =CHOOSE($C$2,N18,N19,N20) -> 0.138
A18: Case 1 | G18: 0.13 | H18: 0.13 | I18: 0.13 | J18: 0.13 | K18: 0.13 | L18: 0.13 | M18: 0.13 | N18: 0.13
A19: Case 2 | G19: 0.155 | H19: =15% -> 0.15 | I19: =14% -> 0.14 | J19: =14% -> 0.14 | K19: =13.8% -> 0.138 | L19: =13.8% -> 0.138 | M19: =13.8% -> 0.138 | N19: =13.8% -> 0.138
A20: Case 3 | G20: 0.175 | H20: 0.175 | I20: 0.175 | J20: 0.175 | K20: 0.175 | L20: 0.175 | M20: 0.175 | N20: 0.175
A22: Employee benefits expenses | B22: 746.97 | C22: 906.12 | D22: 1165.9 | E22: 1541.48 | G22: =G23*G8 -> 1759.3334 | H22: =H23*H8 -> 2040.8267 | I22: =I23*I8 -> 2363.2774 | J22: =J23*J8 -> 2853.6574 | K22: =K23*K8 -> 3295.9743 | L22: =L23*L8 -> 3806.8503 | M22: =M23*M8 -> 4779.2523 | N22: =N23*N8 -> 5520.0364
A23: % of revenue | B23: =B22/B8 -> 0.017436454 | C23: =C22/C8 -> 0.017840931 | D23: =D22/D8 -> 0.019641818 | E23: =E22/E8 -> 0.02239848 | G23: =CHOOSE($C$2,G25,G26,G27) -> 0.022 | H23: =CHOOSE($C$2,H25,H26,H27) -> 0.022 | I23: =CHOOSE($C$2,I25,I26,I27) -> 0.022 | J23: =CHOOSE($C$2,J25,J26,J27) -> 0.023 | K23: =CHOOSE($C$2,K25,K26,K27) -> 0.023 | L23: =CHOOSE($C$2,L25,L26,L27) -> 0.023 | M23: =CHOOSE($C$2,M25,M26,M27) -> 0.025 | N23: =CHOOSE($C$2,N25,N26,N27) -> 0.025
A25: Case 1 | G25: 0.0218 | H25: 0.0218 | I25: 0.0218 | J25: 0.022 | K25: 0.022 | L25: 0.022 | M25: 0.022 | N25: 0.022
A26: Case 2 | G26: 0.022 | H26: 0.022 | I26: 0.022 | J26: 0.023 | K26: 0.023 | L26: 0.023 | M26: 0.025 | N26: 0.025
A27: Case 3 | G27: 0.027 | H27: 0.027 | I27: 0.027 | J27: 0.027 | K27: 0.027 | L27: 0.027 | M27: 0.027 | N27: 0.027
A29: Other expenses | B29: 2071.61 | C29: 2504.4 | D29: 3153.12 | E29: 3632.94 | G29: =G8*G30 -> 4137.6015 | H29: =H8*H30 -> 4777.3899 | I29: =I8*I30 -> 5693.35 | J29: =J8*J30 -> 6575.8193 | K29: =K8*K30 -> 7595.0713 | L29: =L8*L30 -> 8772.3073 | M29: =M8*M30 -> 10132.015 | N29: =N8*N30 -> 11702.477
A30: % of total revenue | B30: =B29/B8 -> 0.048357406 | C30: =C29/C8 -> 0.049310055 | D30: =D29/D8 -> 0.053120343 | E30: =E29/E8 -> 0.052788447 | G30: =CHOOSE($C$2,G32,G33,G34) -> 0.051739615 | H30: =CHOOSE($C$2,H32,H33,H34) -> 0.0515 | I30: =CHOOSE($C$2,I32,I33,I34) -> 0.053 | J30: =CHOOSE($C$2,J32,J33,J34) -> 0.053 | K30: =CHOOSE($C$2,K32,K33,K34) -> 0.053 | L30: =CHOOSE($C$2,L32,L33,L34) -> 0.053 | M30: =CHOOSE($C$2,M32,M33,M34) -> 0.053 | N30: =CHOOSE($C$2,N32,N33,N34) -> 0.053
A32: Case 1 | G32: 0.045 | H32: 0.045 | I32: 0.045 | J32: 0.045 | K32: 0.045 | L32: 0.045 | M32: 0.045 | N32: 0.045
A33: Case 2 | G33: =AVERAGE(C30:E30) -> 0.051739615 | H33: 0.0515 | I33: 0.053 | J33: 0.053 | K33: 0.053 | L33: 0.053 | M33: 0.053 | N33: 0.053
A34: Case 3 | G34: 0.06 | H34: 0.06 | I34: 0.06 | J34: 0.06 | K34: 0.06 | L34: 0.06 | M34: 0.06 | N34: 0.06
A36: Depreciation and amortisation expenses | B36: 638.87 | C36: 730.76 | D36: 869.52 | E36: 1037.02 | G36: =G37*'BS assumptions'!F16 -> 1290.434 | H36: =H37*'BS assumptions'!G16 -> 1628.0789 | I36: =I37*'BS assumptions'!H16 -> 2147.4361 | J36: =J37*'BS assumptions'!I16 -> 2639.3454 | K36: =K37*'BS assumptions'!J16 -> 3481.2966 | L36: =L37*'BS assumptions'!K16 -> 4591.8302 | M36: =M37*'BS assumptions'!L16 -> 5908.9014 | N36: =N37*'BS assumptions'!M16 -> 7793.841
A37: % of PPE | B37: =B36/('Balance Sheet'!B6+'Balance Sheet'!B7+'Balance Sheet'!B8) -> 0.052975833 | C37: =C36/('Balance Sheet'!C6+'Balance Sheet'!C7+'Balance Sheet'!C8) -> 0.051340815 | D37: =D36/('Balance Sheet'!D6+'Balance Sheet'!D7+'Balance Sheet'!D8) -> 0.050580219 | E37: =E36/('Balance Sheet'!E6+'Balance Sheet'!E7+'Balance Sheet'!E8) -> 0.048758905 | G37: =CHOOSE($C$2,G39,G40,G41) -> 0.046 | H37: =CHOOSE($C$2,H39,H40,H41) -> 0.044 | I37: =CHOOSE($C$2,I39,I40,I41) -> 0.044 | J37: =CHOOSE($C$2,J39,J40,J41) -> 0.041 | K37: =CHOOSE($C$2,K39,K40,K41) -> 0.041 | L37: =CHOOSE($C$2,L39,L40,L41) -> 0.041 | M37: =CHOOSE($C$2,M39,M40,M41) -> 0.04 | N37: =CHOOSE($C$2,N39,N40,N41) -> 0.04
A39: Case 1 | G39: 0.04 | H39: 0.04 | I39: 0.04 | J39: 0.04 | K39: 0.035 | L39: 0.035 | M39: 0.035 | N39: 0.035
A40: Case 2 | G40: 0.046 | H40: 0.044 | I40: 0.044 | J40: 0.041 | K40: 0.041 | L40: 0.041 | M40: 0.04 | N40: 0.04
A41: Case 3 | G41: 0.055 | H41: 0.055 | I41: 0.055 | J41: 0.055 | K41: 0.05 | L41: 0.05 | M41: 0.05 | N41: 0.05
A43: Tax | B43: 0.22278757 | C43: 0.26744633 | D43: 0.26281152 | E43: 0.27238204 | G43: =CHOOSE($C$2,G45,G46,G47) -> 0.27 | H43: =CHOOSE($C$2,H45,H46,H47) -> 0.27 | I43: =CHOOSE($C$2,I45,I46,I47) -> 0.27 | J43: =CHOOSE($C$2,J45,J46,J47) -> 0.27 | K43: =CHOOSE($C$2,K45,K46,K47) -> 0.27 | L43: =CHOOSE($C$2,L45,L46,L47) -> 0.27 | M43: =CHOOSE($C$2,M45,M46,M47) -> 0.27 | N43: =CHOOSE($C$2,N45,N46,N47) -> 0.27
A45: Case 1 | G45: 0.25 | H45: 0.25 | I45: 0.25 | J45: 0.25 | K45: 0.25 | L45: 0.25 | M45: 0.25 | N45: 0.25
A46: Case 2 | G46: 0.27 | H46: 0.27 | I46: 0.27 | J46: 0.27 | K46: 0.27 | L46: 0.27 | M46: 0.27 | N46: 0.27
A47: Case 3 | G47: 0.3 | H47: 0.3 | I47: 0.3 | J47: 0.3 | K47: 0.3 | L47: 0.3 | M47: 0.3 | N47: 0.3

Sheet BS assumptions
A1: Balance Sheet Assumptions
F3: Forcast years
A4: INR crores | B4: FY22-23 | C4: FY23-24 | D4: FY24-25 | E4: FY25-26 | F4: FY26-27 | G4: FY27-28 | H4: FY28-29 | I4: FY29-30 | J4: FY30-31 | K4: FY31-32 | L4: FY32-33 | M4: FY33-34
A5: Accounts Receivable | B5: 62.16 | C5: 166.37 | D5: 153.79 | E5: 149.34 | F5: =F6*'P&L Assumptions'!G8/365 -> 146.7937 | G5: =G6*'P&L Assumptions'!H8/365 -> 165.19768 | H5: =H6*'P&L Assumptions'!I8/365 -> 176.58361 | I5: =I6*'P&L Assumptions'!J8/365 -> 203.95407 | J5: =J6*'P&L Assumptions'!K8/365 -> 227.71472 | K5: =K6*'P&L Assumptions'!L8/365 -> 263.01051 | L5: =L6*'P&L Assumptions'!M8/365 -> 303.77713 | M5: =M6*'P&L Assumptions'!N8/365 -> 362.9613
A6: DSO | B6: =(B5/'Ratio analysis'!B5)*365 -> 0.52961328 | C6: =(C5/'Ratio analysis'!C5)*365 -> 1.1956379 | D6: =(D5/'Ratio analysis'!D5)*365 -> 0.94567375 | E6: =(E5/'Ratio analysis'!E5)*365 -> 0.79204467 | F6: 0.67 | G6: 0.65 | H6: 0.6 | I6: 0.6 | J6: 0.58 | K6: 0.58 | L6: 0.58 | M6: 0.6
A8: Accounts Payable | B8: ='Balance Sheet'!B42+'Balance Sheet'!B43 -> 753.79 | C8: ='Balance Sheet'!C42+'Balance Sheet'!C43 -> 984.81 | D8: ='Balance Sheet'!D42+'Balance Sheet'!D43 -> 1070.81 | E8: ='Balance Sheet'!E42+'Balance Sheet'!E43 -> 1338.23 | F8: =F9*'P&L Assumptions'!G15/365 -> 1477.8465 | G8: =G9*'P&L Assumptions'!H15/365 -> 1699.5235 | H8: =H9*'P&L Assumptions'!I15/365 -> 1937.4568 | I8: =I9*'P&L Assumptions'!J15/365 -> 2208.7008 | J8: =J9*'P&L Assumptions'!K15/365 -> 2513.5015 | K8: =K9*'P&L Assumptions'!L15/365 -> 2860.3647 | L8: =L9*'P&L Assumptions'!M15/365 -> 3255.095 | M8: =M9*'P&L Assumptions'!N15/365 -> 3704.2981
A9: DPO | B9: =(B8/('income statement'!B8+'income statement'!B9)*365) -> 7.5619428 | C9: =(C8/('income statement'!C8+'income statement'!C9))*365 -> 8.3064003 | D9: =(D8/('income statement'!D8+'income statement'!D9))*365 -> 7.7316025 | E9: =(E8/('income statement'!E8+'income statement'!E9))*365 -> 8.3553918 | F9: =AVERAGE($B$9:$E$9) -> 7.9888344 | G9: =AVERAGE($B$9:$E$9) -> 7.9888344 | H9: =AVERAGE($B$9:$E$9) -> 7.9888344 | I9: =AVERAGE($B$9:$E$9) -> 7.9888344 | J9: =AVERAGE($B$9:$E$9) -> 7.9888344 | K9: =AVERAGE($B$9:$E$9) -> 7.9888344 | L9: =AVERAGE($B$9:$E$9) -> 7.9888344 | M9: =AVERAGE($B$9:$E$9) -> 7.9888344
A11: Inventory | B11: 3243.48 | C11: 3927.31 | D11: 5044.37 | E11: 5900.64 | F11: =F12*'P&L Assumptions'!G15/365 -> 6807.5955 | G11: =G12*'P&L Assumptions'!H15/365 -> 7190.5228 | H11: =H12*'P&L Assumptions'!I15/365 -> 7954.6754 | I11: =I12*'P&L Assumptions'!J15/365 -> 9068.3299 | J11: =J12*'P&L Assumptions'!K15/365 -> 10319.759 | K11: =K12*'P&L Assumptions'!L15/365 -> 11743.886 | L11: =L12*'P&L Assumptions'!M15/365 -> 13364.543 | M11: =M12*'P&L Assumptions'!N15/365 -> 15208.849
A12: DIO | B12: =(B11/('income statement'!B8+'income statement'!B9))*365 -> 32.538254 | C12: =(C11/('income statement'!C8+'income statement'!C9))*365 -> 33.124977 | D12: =(D11/('income statement'!D8+'income statement'!D9))*365 -> 36.42202 | E12: =(E11/('income statement'!E8+'income statement'!E9))*365 -> 36.84132 | F12: 36.8 | G12: 33.8 | H12: 32.8 | I12: 32.8 | J12: 32.8 | K12: 32.8 | L12: 32.8 | M12: 32.8
A14: CCC | B14: =B12+B6-B9 -> 25.505924 | C14: =C12+C6-C9 -> 26.014215 | D14: =D12+D6-D9 -> 29.636092 | E14: =E12+E6-E9 -> 29.277973 | F14: =F12+F6-F9 -> 29.481166 | G14: =G12+G6-G9 -> 26.461166 | H14: =H12+H6-H9 -> 25.411166 | I14: =I12+I6-I9 -> 25.411166 | ... M14: =M12+M6-M9 -> 25.411166
A16: Property, Plant and Equipment | B16: ='Balance Sheet'!B6+'Balance Sheet'!B7+'Balance Sheet'!B8 -> 12059.65 | C16: ='Balance Sheet'!C6+'Balance Sheet'!C7+'Balance Sheet'!C8 -> 14233.51 | D16: ='Balance Sheet'!D6+'Balance Sheet'!D7+'Balance Sheet'!D8 -> 17190.91 | E16: ='Balance Sheet'!E6+'Balance Sheet'!E7+'Balance Sheet'!E8 -> 21268.32 | F16: =E16*(1+F17) -> 28052.914 | G16: =F16*(1+G17) -> 37001.794 | H16: =G16*(1+H17) -> 48805.366 | I16: =H16*(1+I17) -> 64374.278 | J16: =I16*(1+J17) -> 84909.672 | K16: =J16*(1+K17) -> 111995.86 | L16: =K16*(1+L17) -> 147722.54 | M16: =L16*(1+M17) -> 194846.03
A17: % Sales | B17: =B16/'income statement'!B5 -> 0.28150733 | C17: =C16/'income statement'!C5 -> 0.28024883 | D17: =D16/'income statement'!D5 -> 0.28961379 | E17: =E16/'income statement'!E5 -> 0.3090394 | F17: 0.319 | G17: 0.319 | H17: 0.319 | I17: 0.319 | J17: 0.319 | K17: 0.319 | L17: 0.319 | M17: 0.319

Sheet P&L forcast
A1: P&L
F3: Forcast Years
A5: INR in crores | B5: FY22-23 | C5: FY23-24 | D5: FY24-25 | E5: FY25-26 | F5: FY26-27 | G5: FY27-28 | H5: FY28-29 | I5: FY29-30 | J5: FY30-31 | K5: FY31-32 | L5: FY32-33 | M5: FY33-34
A6: Net Revenue | B6: 42839.56 | C6: 50788.83 | D6: 59358.05 | E6: 68820.74 | F6: ='P&L Assumptions'!G8 -> 79969.7 | G6: ='P&L Assumptions'!H8 -> 92764.852 | H6: ='P&L Assumptions'!I8 -> 107421.7 | I6: ='P&L Assumptions'!J8 -> 124072.06 | J6: ='P&L Assumptions'!K8 -> 143303.23 | K6: ='P&L Assumptions'!L8 -> 165515.23 | L6: ='P&L Assumptions'!M8 -> 191170.09 | M6: ='P&L Assumptions'!N8 -> 220801.46
A7: COGS | B7: 36383.95 | C7: 43274.54 | D7: 50551.7 | E7: 58459.73 | F7: ='P&L Assumptions'!G15 -> 67520.988 | G7: ='P&L Assumptions'!H15 -> 77649.136 | H7: ='P&L Assumptions'!I15 -> 88520.015 | I7: ='P&L Assumptions'!J15 -> 100912.82 | J7: ='P&L Assumptions'!K15 -> 114838.79 | K7: ='P&L Assumptions'!L15 -> 130686.54 | L7: ='P&L Assumptions'!M15 -> 148721.28 | M7: ='P&L Assumptions'!N15 -> 169244.82
A8: Gross Margin | B8: =B6-B7 -> 6455.61 | C8: =C6-C7 -> 7514.29 | D8: =D6-D7 -> 8806.35 | E8: =E6-E7 -> 10361.01 | F8: =F6-F7 -> 12448.712 | G8: =G6-G7 -> 15115.715 | H8: =H6-H7 -> 18901.683 | I8: =I6-I7 -> 23159.244 | ... M8: =M6-M7 -> 51556.639
A10: Employee benefits expenses | B10: 746.97 | C10: 906.12 | D10: 1165.9 | E10: 1541.48 | F10: ='P&L Assumptions'!G22 -> 1759.3334 | G10: ='P&L Assumptions'!H22 -> 2040.8267 | H10: ='P&L Assumptions'!I22 -> 2363.2774 | I10: ='P&L Assumptions'!J22 -> 2853.6574 | J10: ='P&L Assumptions'!K22 -> 3295.9743 | K10: ='P&L Assumptions'!L22 -> 3806.8503 | L10: ='P&L Assumptions'!M22 -> 4779.2523 | M10: ='P&L Assumptions'!N22 -> 5520.0364
A11: Other expenses | B11: 2071.61 | C11: 2504.4 | D11: 3153.12 | E11: 3632.94 | F11: ='P&L Assumptions'!G29 -> 4137.6015 | G11: ='P&L Assumptions'!H29 -> 4777.3899 | H11: ='P&L Assumptions'!I29 -> 5693.35 | I11: ='P&L Assumptions'!J29 -> 6575.8193 | J11: ='P&L Assumptions'!K29 -> 7595.0713 | K11: ='P&L Assumptions'!L29 -> 8772.3073 | L11: ='P&L Assumptions'!M29 -> 10132.015 | M11: ='P&L Assumptions'!N29 -> 11702.477
A12: EBITDA | B12: =B8-(B10+B11) -> 3637.03 | C12: =C8-(C10+C11) -> 4103.77 | D12: =D8-(D10+D11) -> 4487.33 | E12: =E8-(E10+E11) -> 5186.59 | F12: =F8-(F10+F11) -> 6551.7768 | G12: =G8-(G10+G11) -> 8297.4989 | H12: =H8-(H10+H11) -> 10845.056 | I12: =I8-(I10+I11) -> 13729.767 | ... M12: =M8-(M10+M11) -> 34334.126
A14: D&A | B14: 638.87 | C14: 730.76 | D14: 869.52 | E14: 1037.02 | F14: ='P&L Assumptions'!G36 -> 1290.434 | G14: ='P&L Assumptions'!H36 -> 1628.0789 | H14: ='P&L Assumptions'!I36 -> 2147.4361 | I14: ='P&L Assumptions'!J36 -> 2639.3454 | J14: ='P&L Assumptions'!K36 -> 3481.2966 | K14: ='P&L Assumptions'!L36 -> 4591.8302 | L14: ='P&L Assumptions'!M36 -> 5908.9014 | M14: ='P&L Assumptions'!N36 -> 7793.841
A15: EBIT | B15: =B12-B14 -> 2998.16 | C15: =C12-C14 -> 3373.01 | D15: =D12-D14 -> 3617.81 | E15: =E12-E14 -> 4149.57 | F15: =F12-F14 -> 5261.3428 | G15: =G12-G14 -> 6669.42 | H15: =H12-H14 -> 8697.6195 | I15: =I12-I14 -> 11090.422 | ... M15: =M12-M14 -> 26540.285
A17: Taxes | B17: 681.75 | C17: 925.72 | D17: 965.22 | E17: 1111.76 | F17: =F15*F18 -> 1420.5626 | G17: =G15*G18 -> 1800.7434 | H17: =H15*H18 -> 2348.3573 | I17: =I15*I18 -> 2994.4139 | J17: =J15*J18 -> 3804.8677 | K17: =K15*K18 -> 4767.5804 | L17: =L15*L18 -> 5839.7336 | M17: =M15*M18 -> 7165.8769
B18: 0.22278757 | C18: 0.26744633 | D18: 0.26281152 | E18: 0.27238204 | F18: ='P&L Assumptions'!G43 -> 0.27 | G18: ='P&L Assumptions'!H43 -> 0.27 | H18: ='P&L Assumptions'!I43 -> 0.27 | I18: ='P&L Assumptions'!J43 -> 0.27 | J18: ='P&L Assumptions'!K43 -> 0.27 | K18: ='P&L Assumptions'!L43 -> 0.27 | L18: ='P&L Assumptions'!M43 -> 0.27 | M18: ='P&L Assumptions'!N43 -> 0.27
A20: NOPAT | B20: =B15-B17 -> 2316.41 | C20: =C15-C17 -> 2447.29 | D20: =D15-D17 -> 2652.59 | E20: =E15-E17 -> 3037.81 | F20: =F15-F17 -> 3840.7802 | G20: =G15-G17 -> 4868.6766 | H20: =H15-H17 -> 6349.2622 | I20: =I15-I17 -> 8096.0081 | ... M20: =M15-M17 -> 19374.408

Sheet BS Forcast
A1: Balance Sheet
F3: Forcast Years
A4: INR in Crore | B4: FY22-23 | C4: FY23-24 | D4: FY24-25 | E4: FY25-26 | F4: FY26-27 | G4: FY27-28 | H4: FY28-29 | I4: FY29-30 | J4: FY30-31 | K4: FY31-32 | L4: FY32-33 | M4: FY33-34
A5: Property, Plant and Equipment | B5: 12059.65 | C5: 14233.51 | D5: 17190.91 | E5: 21268.32 | F5: ='BS assumptions'!F16 -> 28052.914 | G5: ='BS assumptions'!G16 -> 37001.794 | H5: ='BS assumptions'!H16 -> 48805.366 | I5: ='BS assumptions'!I16 -> 64374.278 | J5: ='BS assumptions'!J16 -> 84909.672 | K5: ='BS assumptions'!K16 -> 111995.86 | L5: ='BS assumptions'!L16 -> 147722.54 | M5: ='BS assumptions'!M16 -> 194846.03
A6: Depriciation and Amortization | B6: ='P&L forcast'!B14 -> 638.87 | C6: ='P&L forcast'!C14 -> 730.76 | D6: ='P&L forcast'!D14 -> 869.52 | E6: ='P&L forcast'!E14 -> 1037.02 | F6: ='P&L forcast'!F14 -> 1290.434 | G6: ='P&L forcast'!G14 -> 1628.0789 | H6: ='P&L forcast'!H14 -> 2147.4361 | I6: ='P&L forcast'!I14 -> 2639.3454 | ... M6: ='P&L forcast'!M14 -> 7793.841
A7: Capex | B7: 2211.49 | C7: 2731.04 | D7: 3423.04 | E7: 4113.35 | F7: =E7*118% -> 4853.753 | G7: =F7*118% -> 5727.4285 | H7: =G7*118% -> 6758.3657 | I7: =H7*118% -> 7974.8715 | J7: =I7*118% -> 9410.3484 | K7: =J7*116% -> 10916.004 | L7: =K7*116% -> 12662.565 | M7: =L7*116% -> 14688.575
A8: Ending PPE | B8: =B5+B7-B6 -> 13632.27 | C8: =C5+C7-C6 -> 16233.79 | D8: =D5+D7-D6 -> 19744.43 | E8: =E5+E7-E6 -> 24344.65 | F8: =F5+F7-F6 -> 31616.233 | G8: =G5+G7-G6 -> 41101.143 | H8: =H5+H7-H6 -> 53416.295 | I8: =I5+I7-I6 -> 69709.804 | ... M8: =M5+M7-M6 -> 201740.76
A10: Accounts receivable | B10: 62.16 | C10: 166.37 | D10: 153.79 | E10: 149.34 | F10: ='BS assumptions'!F5 -> 146.7937 | G10: ='BS assumptions'!G5 -> 165.19768 | H10: ='BS assumptions'!H5 -> 176.58361 | I10: ='BS assumptions'!I5 -> 203.95407 | J10: ='BS assumptions'!J5 -> 227.71472 | K10: ='BS assumptions'!K5 -> 263.01051 | L10: ='BS assumptions'!L5 -> 303.77713 | M10: ='BS assumptions'!M5 -> 362.9613
A11: Accounts Payble | B11: 753.79 | C11: 984.81 | D11: 1070.81 | E11: 1338.23 | F11: ='BS assumptions'!F8 -> 1477.8465 | G11: ='BS assumptions'!G8 -> 1699.5235 | H11: ='BS assumptions'!H8 -> 1937.4568 | I11: ='BS assumptions'!I8 -> 2208.7008 | J11: ='BS assumptions'!J8 -> 2513.5015 | K11: ='BS assumptions'!K8 -> 2860.3647 | L11: ='BS assumptions'!L8 -> 3255.095 | M11: ='BS assumptions'!M8 -> 3704.2981
A12: Inventory | B12: 3243.48 | C12: 3927.31 | D12: 5044.37 | E12: 5900.64 | F12: ='BS assumptions'!F11 -> 6807.5955 | G12: ='BS assumptions'!G11 -> 7190.5228 | H12: ='BS assumptions'!H11 -> 7954.6754 | I12: ='BS assumptions'!I11 -> 9068.3299 | J12: ='BS assumptions'!J11 -> 10319.759 | K12: ='BS assumptions'!K11 -> 11743.886 | L12: ='BS assumptions'!L11 -> 13364.543 | M12: ='BS assumptions'!M11 -> 15208.849
A13: Working Capital | B13: =B10+B12-B11 -> 2551.85 | C13: =C10+C12-C11 -> 3108.87 | D13: =D10+D12-D11 -> 4127.35 | E13: =E10+E12-E11 -> 4711.75 | F13: =F10+F12-F11 -> 5476.5427 | G13: =G10+G12-G11 -> 5656.1969 | H13: =H10+H12-H11 -> 6193.8022 | I13: =I10+I12-I11 -> 7063.5832 | ... M13: =M10+M12-M11 -> 11867.513
A14: Changes in working Capital | B14: 331.5 | C14: =C13-B13 -> 557.02 | D14: =D13-C13 -> 1018.48 | E14: =E13-D13 -> 584.4 | F14: =F13-E13 -> 764.79267 | G14: =G13-F13 -> 179.65425 | H14: =H13-G13 -> 537.60524 | I14: =I13-H13 -> 869.78106 | J14: =J13-I13 -> 970.38947 | ... M14: =M13-L13 -> 1454.2879

Sheet Cash Flow forcast
B2: Terminal value | C2: =M12*(1+4.5%)/(12.45%-4.5%) -> 144924.88
B3: Present value of terminal value | C3: =C2/((1+WACC!B21)^8) -> 56682.913
F5: Forcast
A6: INR in crores | B6: FY22-23 | C6: FY23-24 | D6: FY24-25 | E6: FY25-26 | F6: FY26-27 | G6: FY27-28 | H6: FY28-29 | I6: FY29-30 | J6: FY30-31 | K6: FY31-32 | L6: FY32-33 | M6: FY33-34
A7: Net operating profit after taxes | B7: 2316.41 | C7: 2447.29 | D7: 2652.59 | E7: 3037.81 | F7: ='P&L forcast'!F20 -> 3840.7802 | G7: ='P&L forcast'!G20 -> 4868.6766 | H7: ='P&L forcast'!H20 -> 6349.2622 | I7: ='P&L forcast'!I20 -> 8096.0081 | J7: ='P&L forcast'!J20 -> 10287.235 | K7: ='P&L forcast'!K20 -> 12890.125 | L7: ='P&L forcast'!L20 -> 15788.909 | M7: ='P&L forcast'!M20 -> 19374.408
A8: Add: D&A | B8: ='P&L forcast'!B14 -> 638.87 | C8: ='P&L forcast'!C14 -> 730.76 | D8: ='P&L forcast'!D14 -> 869.52 | E8: ='P&L forcast'!E14 -> 1037.02 | F8: ='P&L forcast'!F14 -> 1290.434 | G8: ='P&L forcast'!G14 -> 1628.0789 | H8: ='P&L forcast'!H14 -> 2147.4361 | I8: ='P&L forcast'!I14 -> 2639.3454 | ... M8: ='P&L forcast'!M14 -> 7793.841
A9: Gross Cash Flow | B9: =B7+B8 -> 2955.28 | C9: =C7+C8 -> 3178.05 | D9: =D7+D8 -> 3522.11 | E9: =E7+E8 -> 4074.83 | F9: =F7+F8 -> 5131.2143 | G9: =G7+G8 -> 6496.7555 | H9: =H7+H8 -> 8496.6983 | I9: =I7+I8 -> 10735.353 | ... M9: =M7+M8 -> 27168.249
A10: less Capex | B10: ='BS Forcast'!B7 -> 2211.49 | C10: ='BS Forcast'!C7 -> 2731.04 | D10: ='BS Forcast'!D7 -> 3423.04 | E10: ='BS Forcast'!E7 -> 4113.35 | F10: ='BS Forcast'!F7 -> 4853.753 | G10: ='BS Forcast'!G7 -> 5727.4285 | H10: ='BS Forcast'!H7 -> 6758.3657 | I10: ='BS Forcast'!I7 -> 7974.8715 | ... M10: ='BS Forcast'!M7 -> 14688.575
A11: less investment in cashflow | B11: ='BS Forcast'!B14 -> 331.5 | C11: ='BS Forcast'!C14 -> 557.02 | D11: ='BS Forcast'!D14 -> 1018.48 | E11: ='BS Forcast'!E14 -> 584.4 | F11: ='BS Forcast'!F14 -> 764.79267 | G11: ='BS Forcast'!G14 -> 179.65425 | H11: ='BS Forcast'!H14 -> 537.60524 | I11: ='BS Forcast'!I14 -> 869.78106 | ... M11: ='BS Forcast'!M14 -> 1454.2879
A12: Net Cash Flow (free cash flow) | B12: =B9-B10-B11 -> 412.29 | C12: =C9-C10-C11 -> -110.01 | D12: =D9-D10-D11 -> -919.41 | E12: =E9-E10-E11 -> -622.92 | F12: =F9-F10-F11 -> -487.33139 | G12: =G9-G10-G11 -> 589.6727 | H12: =H9-H10-H11 -> 1200.7274 | I12: =I9-I10-I11 -> 1890.7009 | ... M12: =M9-M10-M11 -> 11025.386

Sheet WACC
A3: Key inputs:
A4: Total Equity to Capital | B4: =B23/SUM(B23,B24) -> 0.99554124
A5: Net Debt to Capital | B5: =1-B4 -> 0.0044587635
A7: Calculations:
A8: Risk Free Rate | B8: 0.074
A9: Equity Beta | B9: 1.13
A10: Market Risk Premium | B10: 0.045
A11: Cost of Equity | B11: =B8+B9*(B10) -> 0.12485
A13: Pre-tax cost of debt | B13: 0.065
A14: Marginal Tax Rate | B14: 0.27
A15: Cost of Debt | B15: =B13*(1-B14) -> 0.04745
A18: Weighted Cost of Equity | B18: =B4*B11 -> 0.12429332
A19: Weighted Cost of Debt | B19: =B5*B15 -> 0.00021156833
A21: Weighted Average Cost of Capital | B21: =B18+B19 -> 0.12450489
A23: Market Cap | B23: 215523
A24: Debt | B24: 965.27

Sheet DCF Valuation
A1: DCF Valuation
A3: WACC | B3: 0.1245
A4: Terminal growth | B4: 0.045
A7: INR in crores | B7: FY22-23 | C7: FY23-24 | D7: FY24-25 | E7: FY25-26 | F7: FY26-27 | G7: FY27-28 | H7: FY28-29 | I7: FY29-30 | J7: FY30-31 | K7: FY31-32 | L7: FY32-33 | M7: FY33-34
A8: Net cash flow (FCF) | B8: ='Cash Flow forcast'!B12 -> 412.29 | C8: ='Cash Flow forcast'!C12 -> -110.01 | D8: ='Cash Flow forcast'!D12 -> -919.41 | E8: ='Cash Flow forcast'!E12 -> -622.92 | F8: ='Cash Flow forcast'!F12 -> -487.33139 | G8: ='Cash Flow forcast'!G12 -> 589.6727 | H8: ='Cash Flow forcast'!H12 -> 1200.7274 | I8: ='Cash Flow forcast'!I12 -> 1890.7009 | ... M8: ='Cash Flow forcast'!M12 -> 11025.386
A9: Discount Factor | F9: =1/(1+$B$3)^1 -> 0.88928413 | G9: =1/(1+$B$3)^2 -> 0.79082626 | H9: =1/(1+$B$3)^3 -> 0.70326924 | I9: =1/(1+$B$3)^4 -> 0.62540617 | J9: =1/(1+$B$3)^5 -> 0.55616378 | K9: =1/(1+$B$3)^6 -> 0.49458762 | L9: =1/(1+$B$3)^7 -> 0.43982892 | M9: =1/(1+$B$3)^8 -> 0.39113288
A10: Present Value | F10: =F8*F9 -> -433.37607 | G10: =G8*G9 -> 466.32865 | H10: =H8*H9 -> 844.43466 | I10: =I8*I9 -> 1182.456 | J10: =J8*J9 -> 1884.1681 | K10: =K8*K9 -> 2697.18 | L10: =L8*L9 -> 3416.8345 | M10: =M8*M9 -> 4312.3908
A12: DCF Value | B12: =SUM(F10:M10) -> 14370.417 | C12: =B12/B15 -> 0.20224271
A13: Continuing value | B13: =M8*(1+B4)/(B3-B4) -> 144924.88
A14: Present value of CV | B14: =B13*M9 -> 56684.886 | C14: =B14/B15 -> 0.79775729
A15: Enterprise value | B15: =B12+B14 -> 71055.303
A16: less
A17: Debt | B17: =-'Balance Sheet'!E40 -> -965.27
A18: add
A19: ='Balance Sheet'!A9 -> Investment properties | B19: ='Balance Sheet'!E9 -> 7.26
A20: ='Balance Sheet'!A10 -> Goodwill | B20: ='Balance Sheet'!E10 -> 78.27
A21: ='Balance Sheet'!A11 -> Intangible assets | B21: ='Balance Sheet'!E11 -> 36.42
A22: ='Balance Sheet'!A12 -> Financial assets | B22: ='Balance Sheet'!E12 -> 2.01
A23: ='Balance Sheet'!A13 -> Other non-current financial assets | B23: ='Balance Sheet'!E13 -> 196.71
A24: ='Balance Sheet'!A22 -> Investments | B24: 2
A25: ='Balance Sheet'!A24 -> Cash and cash equivalents | B25: ='Balance Sheet'!E24 -> 283.71
A26: ='Balance Sheet'!A25 -> Bank balances other than cash and cash equivalents | B26: ='Balance Sheet'!E25 -> 20.07
A27: ='Balance Sheet'!A26 -> Other current financial assets | B27: ='Balance Sheet'!E26 -> 726.6
A28: ='Balance Sheet'!A27 -> Other current assets | B28: ='Balance Sheet'!E27 -> 395.42
A29: Equity Value | B29: =B15+SUM(B17:B28) -> 71838.503
A30: shares outstanding | B30: 65.197
A32: per share value | B32: =B29/B30 -> 1101.8682

Sheet sensitivity analysis
A1: Sensitivity Table
C3: WACC
B4: ='DCF Valuation'!B32 -> 1101.8682 | C4: 0.1145 | D4: 0.1245 | E4: 0.1345 | F4: 0.1445 | G4: 0.1545
A5: Terminal growth rate | B5: 0.04 | C5: 1237 | D5: 1046.51 | E5: 898.49 | F5: 780.7 | G5: 685.12
B6: 0.045 | C6: 1313.6 | D6: 1101.87 | E6: 939.81 | F6: 812.32 | G6: 709.79
B7: 0.05 | C7: 1401.91 | D7: 1164.66 | E7: 986.03 | F7: 847.28 | G7: 736.82
B8: 0.055 | C8: 1505.07 | D8: 1236.48 | E8: 1038.07 | F8: 886.14 | G8: 766.57
B9: 0.06 | C9: 1627 | D9: 1319.45 | E9: 1097.08 | F9: 929.61 | G9: 799.46

Sheet Sheet1
A1: 44652 | B1: 3944.25 | I1: 44652 | J1: 17102.55
A2: 44682 | B2: 3972.8 | G2: 0.0072 | I2: 44682 | J2: 16584.55 | O2: -0.0303
A3: 44713 | B3: 3406.1 | G3: -0.1426 | I3: 44713 | J3: 15780.25 | O3: -0.0485
A4: 44743 | B4: 4243.85 | D4: =SLOPE(G2:G55,O2:O55) -> 1.1266136 | G4: 0.246 | I4: 44743 | J4: 17158.25 | O4: 0.0873
A5: 44774 | B5: 4531.35 | G5: 0.0677 | I5: 44774 | J5: 17759.3 | O5: 0.035
A6: 44805 | B6: 4386.55 | G6: -0.032 | I6: 44805 | J6: 17094.35 | O6: -0.0374
A7: 44835 | B7: 4320.9 | G7: -0.015 | I7: 44835 | J7: 18012.2 | O7: 0.0537
A8: 44866 | B8: 4025.5 | G8: -0.0684 | I8: 44866 | J8: 18758.35 | O8: 0.0414
A9: 44896 | B9: 4068.75 | G9: 0.0107 | I9: 44896 | J9: 18105.3 | O9: -0.0348
A10: 44927 | B10: 3502.3 | G10: -0.1392 | I10: 44927 | J10: 17662.15 | O10: -0.0245
A11: 44958 | B11: 3416.95 | G11: -0.0244 | I11: 44958 | J11: 17303.95 | O11: -0.0203
A12: 44986 | B12: 3401.05 | G12: -0.0047 | I12: 44986 | J12: 17359.75 | O12: 0.0032
A13: 45017 | B13: 3511.95 | G13: 0.0326 | I13: 45017 | J13: 18065 | O13: 0.0406
A14: 45047 | B14: 3471.25 | G14: -0.0116 | I14: 45047 | J14: 18534.4 | O14: 0.026
A15: 45078 | B15: 3889.2 | G15: 0.1204 | I15: 45078 | J15: 19189.05 | O15: 0.0353
A16: 45108 | B16: 3752.8 | G16: -0.0351 | I16: 45108 | J16: 19753.8 | O16: 0.0294
... A54: 46266 | B54: 3801.4 | G54: -0.0253 | I54: 46266 | J54: 22620.45 | O54: -0.0606
A55: 46296 | B55: 3304 | G55: =(B55-B54)/B55 -> -0.15054479 | I55: 46296 | J55: 23146.15 | O55: 0.0232
